Workbook
Name Sales_FY23: 'Inputs'!$B$5
Name Sales_FY24: 'Inputs'!$C$5
Name COGS_FY23: 'Inputs'!$B$6
Name COGS_FY24: 'Inputs'!$C$6
Name GrossProfit_FY23: 'Inputs'!$B$7
Name GrossProfit_FY24: 'Inputs'!$C$7
Name OpEx_FY23: 'Inputs'!$B$8
Name OpEx_FY24: 'Inputs'!$C$8
Name Depreciation_FY23: 'Inputs'!$B$9
Name Depreciation_FY24: 'Inputs'!$C$9
Name EBIT_FY23: 'Inputs'!$B$10
Name EBIT_FY24: 'Inputs'!$C$10
Name Interest_FY23: 'Inputs'!$B$11
Name Interest_FY24: 'Inputs'!$C$11
Name EBT_FY23: 'Inputs'!$B$12
Name EBT_FY24: 'Inputs'!$C$12
Name NetIncome_FY23: 'Inputs'!$B$14
Name NetIncome_FY24: 'Inputs'!$C$14
Name Cash_FY23: 'Inputs'!$B$20
Name Cash_FY24: 'Inputs'!$C$20
Name AR_FY23: 'Inputs'!$B$22
Name AR_FY24: 'Inputs'!$C$22
Name Inventory_FY23: 'Inputs'!$B$23
Name Inventory_FY24: 'Inputs'!$C$23
Name CurrentAssets_FY23: 'Inputs'!$B$25
Name CurrentAssets_FY24: 'Inputs'!$C$25
Name NetFixedAssets_FY23: 'Inputs'!$B$26
Name NetFixedAssets_FY24: 'Inputs'!$C$26
Name TotalAssets_FY23: 'Inputs'!$B$27
Name TotalAssets_FY24: 'Inputs'!$C$27
Name AP_FY23: 'Inputs'!$B$28
Name AP_FY24: 'Inputs'!$C$28
Name CurrentLiab_FY23: 'Inputs'!$B$30
Name CurrentLiab_FY24: 'Inputs'!$C$30
Name LongTermDebt_FY23: 'Inputs'!$B$31
Name LongTermDebt_FY24: 'Inputs'!$C$31
Name TotalLiab_FY23: 'Inputs'!$B$32
Name TotalLiab_FY24: 'Inputs'!$C$32
Name TotalEquity_FY23: 'Inputs'!$B$35
Name TotalEquity_FY24: 'Inputs'!$C$35
Name CFO_FY23: 'Inputs'!$B$38
Name CFO_FY24: 'Inputs'!$C$38
Name CFI_FY23: 'Inputs'!$B$39
Name CFI_FY24: 'Inputs'!$C$39
Name CFF_FY23: 'Inputs'!$B$40
Name CFF_FY24: 'Inputs'!$C$40
Name NetChangeCash_FY23: 'Inputs'!$B$41
Name NetChangeCash_FY24: 'Inputs'!$C$41
Name CapEx_FY23: 'Inputs'!$B$43
Name CapEx_FY24: 'Inputs'!$C$43
Name Price: 'Assumptions'!$B$4
Name SharesOut: 'Assumptions'!$B$5
Name BookValuePS: 'Assumptions'!$B$6
Name DPS: 'Assumptions'!$B$7
Name GrowthG: 'Assumptions'!$B$8
Name Rf: 'Assumptions'!$B$9
Name MarketReturn: 'Assumptions'!$B$10
Name Beta: 'Assumptions'!$B$11
Name RequiredReturnK: 'Assumptions'!$B$12
Name TaxRate: 'Assumptions'!$B$13

Sheet Inputs
A1: Riverside Coffee Roasters LLC -- Raw Inputs
A3: Line item ($, except per-share) | B3: FY23 | C3: FY24
A4: Income Statement
A5: Revenue (Sales) | B5: 1680000 | C5: 1950000
A6: Cost of Goods Sold | B6: 680000 | C6: 765000
A7: Gross Profit | B7: 1000000 | C7: 1185000
A8: Operating / Admin Expenses | B8: 805000 | C8: 930000
A9: Depreciation & Amortization | B9: 48000 | C9: 52000
A10: EBIT (Operating Income) | B10: 147000 | C10: 203000
A11: Interest Expense | B11: 30000 | C11: 31000
A12: Earnings Before Tax | B12: 117000 | C12: 172000
A13: Income Taxes
A14: Net Income | B14: 117000 | C14: 172000
A15: Preferred Dividends
A16: Diluted Shares Outstanding
A17: Earnings per Share (diluted)
A19: Balance Sheet
A20: Cash & Equivalents | B20: 85000 | C20: 130000
A21: Marketable Securities
A22: Accounts Receivable | B22: 42000 | C22: 48000
A23: Inventory | B23: 82000 | C23: 95000
A24: Other Current Assets
A25: Total Current Assets | B25: 220000 | C25: 285000
A26: Net Fixed Assets | B26: 440000 | C26: 470000
A27: Total Assets | B27: 660000 | C27: 755000
A28: Accounts Payable | B28: 72000 | C28: 80000
A29: Other Current Liabilities
A30: Total Current Liabilities | B30: 100000 | C30: 110000
A31: Long-Term Debt | B31: 285000 | C31: 265000
A32: Total Liabilities | B32: 385000 | C32: 375000
A33: Preferred Equity
A34: Common Equity
A35: Total Equity | B35: 275000 | C35: 380000
A37: Cash Flow
A38: Cash Flow from Operations | B38: 158000 | C38: 205000
A39: Cash Flow from Investing | B39: -68000 | C39: -82000
A40: Cash Flow from Financing | B40: -65000 | C40: -78000
A41: Net Change in Cash | B41: 25000 | C41: 45000
A42: Lease Payments
A43: Capital Expenditures | B43: -68000 | C43: -82000
...

Sheet Assumptions
A1: Market & Policy Assumptions (editable)
A3: Assumption | B3: Value | C3: Notes
A4: Price Per Share | C4: Current market price per share
A5: Shares Outstanding | C5: Shares outstanding
A6: Book Value Per Share | C6: Book value per share
A7: Dividend Per Share | C7: Annual dividend per share (D0)
A8: Dividend Growth G | C8: g -- dividend growth (decimal, < required return)
A9: Risk Free Rate | C9: Rf -- 10Y Treasury or user input (decimal)
A10: Market Return | C10: E(Rm) -- expected market return (decimal)
A11: Beta | C11: Equity beta
A12: Required Return K | C12: k -- required return / WACC override (decimal)
A13: Tax Rate | C13: T -- marginal tax rate (decimal)
A14: Flotation Cost | B14: 0 | C14: f -- flotation cost (decimal)
A15: Weight Debt | C15: Capital-structure weight of debt (optional)
A16: Weight Preferred | C16: Weight of preferred (optional)
A17: Weight Equity | C17: Weight of equity (optional)
A18: Cost Of Debt Pretax | C18: Pre-tax cost of debt / YTM (decimal)
A20: Educational analysis only -- NOT investment, tax, or legal advice. Consult a licensed advisor before acting. Every figure ties to an input cell or cited SEC filing; missing inputs are excluded, never invented.

Sheet Ratios
A1: Ratio Analysis -- live formulas (sec 4.1-4.5)
A3: Metric | B3: Category | C3: FY23 | D3: FY24 | E3: Excel formula (latest period) | F3: Interpretation
A4: Current Ratio | B4: Liquidity | C4: =CurrentAssets_FY23/CurrentLiab_FY23 | D4: =CurrentAssets_FY24/CurrentLiab_FY24 | E4: CurrentAssets_FY24/CurrentLiab_FY24 | F4: Current assets per $1 of current liabilities; >1 covers near-term bills.
A5: Quick (Acid-Test) Ratio | B5: Liquidity | C5: =(CurrentAssets_FY23-Inventory_FY23)/CurrentLiab_FY23 | D5: =(CurrentAssets_FY24-Inventory_FY24)/CurrentLiab_FY24 | E5: (CurrentAssets_FY24-Inventory_FY24)/CurrentLiab_FY24 | F5: Liquidity excluding inventory; >1 is conservative coverage.
A6: Net Working Capital | B6: Liquidity | C6: =CurrentAssets_FY23-CurrentLiab_FY23 | D6: =CurrentAssets_FY24-CurrentLiab_FY24 | E6: CurrentAssets_FY24-CurrentLiab_FY24 | F6: Current assets minus current liabilities; the operating cushion.
A7: NWC-to-Total-Assets | B7: Liquidity | C7: =(CurrentAssets_FY23-CurrentLiab_FY23)/TotalAssets_FY23 | D7: =(CurrentAssets_FY24-CurrentLiab_FY24)/TotalAssets_FY24 | E7: (CurrentAssets_FY24-CurrentLiab_FY24)/TotalAssets_FY24 | F7: Share of assets funded as working-capital cushion.
A8: Inventory Turnover | B8: Activity | C8: =COGS_FY23/Inventory_FY23 | D8: =COGS_FY24/AVERAGE(Inventory_FY24,Inventory_FY23) | E8: COGS_FY24/AVERAGE(Inventory_FY24,Inventory_FY23) | F8: Times inventory sold per year; higher = leaner stock.
A9: Days Sales in Inventory | B9: Activity | C9: =365/(COGS_FY23/Inventory_FY23) | D9: =365/(COGS_FY24/AVERAGE(Inventory_FY24,Inventory_FY23)) | E9: 365/(COGS_FY24/AVERAGE(Inventory_FY24,Inventory_FY23)) | F9: Days of inventory on hand; lower = faster conversion to cash.
A10: Collection Period (DSO) | B10: Activity | C10: =AR_FY23/(Sales_FY23/365) | D10: =AR_FY24/(Sales_FY24/365) | E10: AR_FY24/(Sales_FY24/365) | F10: Average days to collect receivables; lower is better.
A11: Fixed Asset Turnover | B11: Activity | C11: =Sales_FY23/NetFixedAssets_FY23 | D11: =Sales_FY24/NetFixedAssets_FY24 | E11: Sales_FY24/NetFixedAssets_FY24 | F11: Sales generated per $1 of net fixed assets.
A12: Total Asset Turnover | B12: Activity | C12: =Sales_FY23/TotalAssets_FY23 | D12: =Sales_FY24/TotalAssets_FY24 | E12: Sales_FY24/TotalAssets_FY24 | F12: Sales generated per $1 of total assets.
A13: Debt Ratio | B13: Leverage | C13: =TotalLiab_FY23/TotalAssets_FY23 | D13: =TotalLiab_FY24/TotalAssets_FY24 | E13: TotalLiab_FY24/TotalAssets_FY24 | F13: Share of assets financed by liabilities; lower = less risk.
A14: Debt-to-Equity (LT) | B14: Leverage | C14: =LongTermDebt_FY23/TotalEquity_FY23 | D14: =LongTermDebt_FY24/TotalEquity_FY24 | E14: LongTermDebt_FY24/TotalEquity_FY24 | F14: Long-term debt per $1 of equity.
A15: Total Debt-to-Equity | B15: Leverage | C15: =TotalLiab_FY23/TotalEquity_FY23 | D15: =TotalLiab_FY24/TotalEquity_FY24 | E15: TotalLiab_FY24/TotalEquity_FY24 | F15: All liabilities per $1 of equity.
A16: Times Interest Earned | B16: Leverage | C16: =EBIT_FY23/Interest_FY23 | D16: =EBIT_FY24/Interest_FY24 | E16: EBIT_FY24/Interest_FY24 | F16: EBIT coverage of interest; >3 is comfortable.
A17: Cash Coverage | B17: Leverage | C17: =(EBIT_FY23+Depreciation_FY23)/Interest_FY23 | D17: =(EBIT_FY24+Depreciation_FY24)/Interest_FY24 | E17: (EBIT_FY24+Depreciation_FY24)/Interest_FY24 | F17: Interest coverage adding back non-cash depreciation.
A18: Fixed Charge Coverage | B18: Leverage | C18: n/a | D18: n/a | E18: (EBIT_FY24+LeasePayments_FY24)/(Interest_FY24+LeasePayments_FY24) | F18: Coverage of interest + lease obligations.
A19: Equity Multiplier | B19: Leverage | C19: =TotalAssets_FY23/TotalEquity_FY23 | D19: =TotalAssets_FY24/TotalEquity_FY24 | E19: TotalAssets_FY24/TotalEquity_FY24 | F19: Assets per $1 of equity; the leverage factor in DuPont.
A20: Gross Profit Margin | B20: Profitability | C20: =GrossProfit_FY23/Sales_FY23 | D20: =GrossProfit_FY24/Sales_FY24 | E20: GrossProfit_FY24/Sales_FY24 | F20: Gross profit per $1 of sales.
A21: Net Profit Margin | B21: Profitability | C21: =NetIncome_FY23/Sales_FY23 | D21: =NetIncome_FY24/Sales_FY24 | E21: NetIncome_FY24/Sales_FY24 | F21: Bottom-line profit per $1 of sales.
A22: Return on Assets (ROA) | B22: Profitability | C22: =NetIncome_FY23/TotalAssets_FY23 | D22: =NetIncome_FY24/TotalAssets_FY24 | E22: NetIncome_FY24/TotalAssets_FY24 | F22: Net income per $1 of assets.
A23: Return on Equity (ROE) | B23: Profitability | C23: =NetIncome_FY23/TotalEquity_FY23 | D23: =NetIncome_FY24/TotalEquity_FY24 | E23: NetIncome_FY24/TotalEquity_FY24 | F23: Net income per $1 of equity.
A24: Earnings per Share (EPS) | B24: Profitability | C24: n/a | D24: n/a | E24: (NetIncome_FY24)/DilutedShares_FY24 | F24: Earnings attributable to each common share.
A25: Price/Earnings (P/E) | B25: Profitability | C25: n/a | D25: n/a | E25: Price/EPS_FY24 | F25: Price paid per $1 of annual earnings.
A26: Market-to-Book | B26: Profitability | C26: n/a | D26: n/a | E26: Price/BookValuePS | F26: Market price relative to accounting book value per share.
A27: ROE (DuPont 3-step) | B27: DuPont | C27: =(NetIncome_FY23/Sales_FY23)*(Sales_FY23/TotalAssets_FY23)*(TotalAssets_FY23/TotalEquity_FY23) | D27: =(NetIncome_FY24/Sales_FY24)*(Sales_FY24/TotalAssets_FY24)*(TotalAssets_FY24/TotalEquity_FY24) | E27: (NetIncome_FY24/Sales_FY24)*(Sales_FY24/TotalAssets_FY24)*(TotalAssets_FY24/TotalEquity_FY24) | F27: ROE = Net Margin x Asset Turnover x Equity Multiplier.
A28: ROE (ROA x leverage) | B28: DuPont | C28: =(NetIncome_FY23/TotalAssets_FY23)*(1+TotalLiab_FY23/TotalEquity_FY23) | D28: =(NetIncome_FY24/TotalAssets_FY24)*(1+TotalLiab_FY24/TotalEquity_FY24) | E28: (NetIncome_FY24/TotalAssets_FY24)*(1+TotalLiab_FY24/TotalEquity_FY24) | F28: Cross-check: ROE = ROA x (1 + Total Debt/Equity).
A30: Green = healthy, red = weak (vs. generic thresholds; fills reflect loaded data).
A32: Educational analysis only -- NOT investment, tax, or legal advice. Consult a licensed advisor before acting. Every figure ties to an input cell or cited SEC filing; missing inputs are excluded, never invented.

Sheet Valuation
A1: Valuation -- WACC / DCF / Gordon / Multiples
A3: Cost of Capital
A4: After-tax cost of debt k_d | B4: =(1-'Assumptions'!$B$13)*'Assumptions'!$B$18 | C4: (1 - T) x pre-tax YTM
A5: Cost of equity k_e (CAPM) | B5: ='Assumptions'!$B$9+'Assumptions'!$B$11*('Assumptions'!$B$10-'Assumptions'!$B$9) | C5: Rf + beta x (E(Rm) - Rf)
A6: Cost of preferred k_p | B6: =IF('Assumptions'!$B$4=0,0,'Assumptions'!$B$7/('Assumptions'!$B$4*(1-'Assumptions'!$B$14))) | C6: D_p / (P_p (1 - f)) [proxy]
A7: Weight of debt W_d | B7: =IF(('Inputs'!$C$31+'Inputs'!$C$35)=0,0,'Inputs'!$C$31/('Inputs'!$C$31+'Inputs'!$C$35)) | C7: Market/structure weight
A8: Weight of equity W_e | B8: =IF(('Inputs'!$C$31+'Inputs'!$C$35)=0,0,'Inputs'!$C$35/('Inputs'!$C$31+'Inputs'!$C$35))
A9: WACC | B9: =B7*B4+B8*B5 | C9: W_d k_d + W_e k_e
A11: Discounted Cash Flow (illustrative)
A12: Base free cash flow (CFO - CapEx) | B12: ='Inputs'!$C$38-'Inputs'!$C$43 | C12: From latest cash-flow statement
A13: Projection growth g (Assumptions) | B13: ='Assumptions'!$B$8
A14: Year | B14: 1 | C14: 2 | D14: 3 | E14: 4 | F14: 5 | G14: Terminal
A15: Projected FCF | B15: =B12*(1+B13) | C15: =B15*(1+B13) | D15: =C15*(1+B13) | E15: =D15*(1+B13) | F15: =E15*(1+B13) | G15: =IF((B9-B13)<=0,0,F15*(1+B13)/(B9-B13))
A16: PV of explicit FCF (yrs 1-5) | B16: =NPV(B9,C15:F15)
A17: PV of terminal value | B17: =G15/((1+B9)^5)
A18: Enterprise value (DCF) | B18: =B16+B17
A19: Intrinsic value per share (EV/shares) | B19: =IF('Assumptions'!$B$5=0,0,B18/'Assumptions'!$B$5)
A20: Market price per share | B20: ='Assumptions'!$B$4
A21: Upside / (downside) vs market | B21: =IF('Assumptions'!$B$4=0,0,B19/'Assumptions'!$B$4-1)
A23: Cross-checks
A24: Gordon-growth value = D0(1+g)/(k_e - g) | B24: =IF((B5-B13)<=0,0,'Assumptions'!$B$7*(1+B13)/(B5-B13))
A26: Educational analysis only -- NOT investment, tax, or legal advice. Consult a licensed advisor before acting. Every figure ties to an input cell or cited SEC filing; missing inputs are excluded, never invented.

Sheet CapBudget
A1: Capital Budgeting -- editable project (sec 4.7)
A2: Edit the cash flows; NPV / IRR / PI / payback recalc live.
A4: Required return k (uses WACC if set) | B4: =IF(Valuation!B9>0,Valuation!B9,Assumptions!$B$12)
A6: Year | B6: 0 | C6: 1 | D6: 2 | E6: 3 | F6: 4 | G6: 5
A7: Net cash flow (NCF) | B7: -100000 | C7: 30000 | D7: 35000 | E7: 40000 | F7: 30000 | G7: 25000
A8: Cumulative cash flow | B8: =B7 | C8: =B8+C7 | D8: =C8+D7 | E8: =D8+E7 | F8: =E8+F7 | G8: =F8+G7
A10: NPV | B10: =B7+NPV(B4,C7:G7) | D10: =-outlay + PV(future NCF)
A11: IRR | B11: =IRR(B7:G7)
A12: Profitability Index (PI) | B12: =IF(B7=0,0,NPV(B4,C7:G7)/-B7) | D12: PV future / initial outlay
A13: Payback (yrs, approx) | B13: =MATCH(TRUE,INDEX(C8:G8>=0,0),0) | D13: First year cumulative >= 0
A14: Accounting Rate of Return (ARR) | B14: =AVERAGE(C7:G7)/(-B7/2) | D14: avg income / avg book value
A16: Decision rules
A17: NPV rule (>0 accept) | B17: =IF(B10>0,"ACCEPT","REJECT")
A18: IRR rule (>k accept) | B18: =IF(B11>B4,"ACCEPT","REJECT")
A19: PI rule (>1 accept) | B19: =IF(B12>1,"ACCEPT","REJECT")
A21: NPV profile (for chart)
A22: Discount rate | B22: NPV
A23: 0 | B23: =B7+NPV(A23,C7:G7)
A24: 0.05 | B24: =B7+NPV(A24,C7:G7)
A25: 0.1 | B25: =B7+NPV(A25,C7:G7)
A26: 0.15 | B26: =B7+NPV(A26,C7:G7)
A27: 0.2 | B27: =B7+NPV(A27,C7:G7)
A28: 0.25 | B28: =B7+NPV(A28,C7:G7)
A29: 0.3 | B29: =B7+NPV(A29,C7:G7)
A31: Educational analysis only -- NOT investment, tax, or legal advice. Consult a licensed advisor before acting. Every figure ties to an input cell or cited SEC filing; missing inputs are excluded, never invented.

Sheet Charts
A1: Charts
A22: Intrinsic vs Market (per share)
A23: Intrinsic | B23: =Valuation!B19
A24: Market | B24: =Assumptions!$B$4
A60: Educational analysis only -- NOT investment, tax, or legal advice. Consult a licensed advisor before acting. Every figure ties to an input cell or cited SEC filing; missing inputs are excluded, never invented.
