Workbook
Name Sales_FY23: 'Inputs'!$B$5
Name Sales_FY24: 'Inputs'!$C$5
Name Sales_FY25: 'Inputs'!$D$5
Name Sales_FY26: 'Inputs'!$E$5
Name COGS_FY23: 'Inputs'!$B$6
Name COGS_FY24: 'Inputs'!$C$6
Name COGS_FY25: 'Inputs'!$D$6
Name COGS_FY26: 'Inputs'!$E$6
Name GrossProfit_FY23: 'Inputs'!$B$7
Name GrossProfit_FY24: 'Inputs'!$C$7
Name GrossProfit_FY25: 'Inputs'!$D$7
Name GrossProfit_FY26: 'Inputs'!$E$7
Name Depreciation_FY23: 'Inputs'!$B$9
Name Depreciation_FY24: 'Inputs'!$C$9
Name Depreciation_FY25: 'Inputs'!$D$9
Name Depreciation_FY26: 'Inputs'!$E$9
Name EBIT_FY23: 'Inputs'!$B$10
Name EBIT_FY24: 'Inputs'!$C$10
Name EBIT_FY25: 'Inputs'!$D$10
Name EBIT_FY26: 'Inputs'!$E$10
Name Interest_FY23: 'Inputs'!$B$11
Name Interest_FY24: 'Inputs'!$C$11
Name Interest_FY25: 'Inputs'!$D$11
Name Interest_FY26: 'Inputs'!$E$11
Name EBT_FY23: 'Inputs'!$B$12
Name EBT_FY24: 'Inputs'!$C$12
Name EBT_FY25: 'Inputs'!$D$12
Name EBT_FY26: 'Inputs'!$E$12
Name Taxes_FY23: 'Inputs'!$B$13
Name Taxes_FY24: 'Inputs'!$C$13
Name Taxes_FY25: 'Inputs'!$D$13
Name Taxes_FY26: 'Inputs'!$E$13
Name NetIncome_FY23: 'Inputs'!$B$14
Name NetIncome_FY24: 'Inputs'!$C$14
Name NetIncome_FY25: 'Inputs'!$D$14
Name NetIncome_FY26: 'Inputs'!$E$14
Name DilutedShares_FY23: 'Inputs'!$B$16
Name DilutedShares_FY24: 'Inputs'!$C$16
Name DilutedShares_FY25: 'Inputs'!$D$16
Name DilutedShares_FY26: 'Inputs'!$E$16
Name EPS_FY23: 'Inputs'!$B$17
Name EPS_FY24: 'Inputs'!$C$17
Name EPS_FY25: 'Inputs'!$D$17
Name EPS_FY26: 'Inputs'!$E$17
Name Cash_FY23: 'Inputs'!$B$20
Name Cash_FY24: 'Inputs'!$C$20
Name Cash_FY25: 'Inputs'!$D$20
Name Cash_FY26: 'Inputs'!$E$20
Name AR_FY23: 'Inputs'!$B$22
Name AR_FY24: 'Inputs'!$C$22
Name AR_FY25: 'Inputs'!$D$22
Name AR_FY26: 'Inputs'!$E$22
Name Inventory_FY23: 'Inputs'!$B$23
Name Inventory_FY24: 'Inputs'!$C$23
Name Inventory_FY25: 'Inputs'!$D$23
Name Inventory_FY26: 'Inputs'!$E$23
Name CurrentAssets_FY23: 'Inputs'!$B$25
Name CurrentAssets_FY24: 'Inputs'!$C$25
Name CurrentAssets_FY25: 'Inputs'!$D$25
Name CurrentAssets_FY26: 'Inputs'!$E$25

Sheet Inputs
A1: WALMART INC. -- Raw Inputs
A3: Line item ($, except per-share) | B3: FY23 | C3: FY24 | D3: FY25 | E3: FY26
A4: Income Statement
A5: Revenue (Sales) | B5: 605881000000 | C5: 642637000000 | D5: 674538000000 | E5: 706413000000
A6: Cost of Goods Sold | B6: 463721000000 | C6: 490142000000 | D6: 511753000000 | E6: 535395000000
A7: Gross Profit | B7: 142160000000 | C7: 152495000000 | D7: 162785000000 | E7: 171018000000
A8: Operating / Admin Expenses
A9: Depreciation & Amortization | B9: 10945000000 | C9: 11853000000 | D9: 12973000000 | E9: 14203000000
A10: EBIT (Operating Income) | B10: 20428000000 | C10: 27012000000 | D10: 29348000000 | E10: 29825000000
A11: Interest Expense | B11: 1787000000 | C11: 2259000000 | D11: 2249000000 | E11: 2318000000
A12: Earnings Before Tax | B12: 17016000000 | C12: 21848000000 | D12: 26309000000 | E12: 29469000000
A13: Income Taxes | B13: 5724000000 | C13: 5578000000 | D13: 6152000000 | E13: 7199000000
A14: Net Income | B14: 11680000000 | C14: 15511000000 | D14: 19436000000 | E14: 21893000000
A15: Preferred Dividends
A16: Diluted Shares Outstanding | B16: 2734000000 | C16: 8108000000 | D16: 8081000000 | E16: 8022000000
A17: Earnings per Share (diluted) | B17: 4.27 | C17: 1.91 | D17: 2.41 | E17: 2.73
A19: Balance Sheet
A20: Cash & Equivalents | B20: 8625000000 | C20: 9867000000 | D20: 9037000000 | E20: 10727000000
A21: Marketable Securities
A22: Accounts Receivable | B22: 7933000000 | C22: 8796000000 | D22: 9975000000 | E22: 11172000000
A23: Inventory | B23: 56576000000 | C23: 54892000000 | D23: 56435000000 | E23: 58851000000
A24: Other Current Assets
A25: Total Current Assets | B25: 75655000000 | C25: 76877000000 | D25: 79458000000 | E25: 84874000000
A26: Net Fixed Assets | B26: 100760000000 | C26: 110810000000 | D26: 119993000000 | E26: 136083000000
A27: Total Assets | B27: 243197000000 | C27: 252399000000 | D27: 260823000000 | E27: 284668000000
A28: Accounts Payable | B28: 53742000000 | C28: 56812000000 | D28: 58666000000 | E28: 63061000000
A29: Other Current Liabilities
A30: Total Current Liabilities | B30: 92198000000 | C30: 92415000000 | D30: 96584000000 | E30: 107469000000
A31: Long-Term Debt | B31: 34649000000 | C31: 36132000000 | D31: 33401000000 | E31: 34624000000
A32: Total Liabilities | B32: 159443000000 | C32: 162050000000 | D32: 163402000000 | E32: 178781000000
A33: Preferred Equity
A34: Common Equity | B34: 76693000000 | C34: 83861000000 | D34: 91013000000 | E34: 99617000000
A35: Total Equity | B35: 83754000000 | C35: 90349000000 | D35: 97421000000 | E35: 105887000000
A37: Cash Flow
A38: Cash Flow from Operations | B38: 28841000000 | C38: 35726000000 | D38: 36443000000 | E38: 41565000000
A39: Cash Flow from Investing | B39: -17722000000 | C39: -21287000000 | D39: -21379000000 | E39: -26350000000
A40: Cash Flow from Financing | B40: -17039000000 | C40: -13414000000 | D40: -14822000000 | E40: -13553000000
A41: Net Change in Cash | B41: -5993000000 | C41: 1094000000 | D41: -399000000 | E41: 1785000000
A42: Lease Payments | B42: 2280000000 | C42: 2273000000 | D42: 2390000000 | E42: 2315000000
A43: Capital Expenditures | B43: 16857000000 | C43: 20606000000 | D43: 23783000000 | E43: 26642000000
...

Sheet Assumptions
A1: Market & Policy Assumptions (editable)
A3: Assumption | B3: Value | C3: Notes
A4: Price Per Share | C4: Current market price per share
A5: Shares Outstanding | C5: Shares outstanding
A6: Book Value Per Share | C6: Book value per share
A7: Dividend Per Share | C7: Annual dividend per share (D0)
A8: Dividend Growth G | C8: g -- dividend growth (decimal, < required return)
A9: Risk Free Rate | C9: Rf -- 10Y Treasury or user input (decimal)
A10: Market Return | C10: E(Rm) -- expected market return (decimal)
A11: Beta | C11: Equity beta
A12: Required Return K | C12: k -- required return / WACC override (decimal)
A13: Tax Rate | C13: T -- marginal tax rate (decimal)
A14: Flotation Cost | B14: 0 | C14: f -- flotation cost (decimal)
A15: Weight Debt | C15: Capital-structure weight of debt (optional)
A16: Weight Preferred | C16: Weight of preferred (optional)
A17: Weight Equity | C17: Weight of equity (optional)
A18: Cost Of Debt Pretax | C18: Pre-tax cost of debt / YTM (decimal)
A20: Educational analysis only -- NOT investment, tax, or legal advice. Consult a licensed advisor before acting. Every figure ties to an input cell or cited SEC filing; missing inputs are excluded, never invented.

Sheet Ratios
A1: Ratio Analysis -- live formulas (sec 4.1-4.5)
A3: Metric | B3: Category | C3: FY23 | D3: FY24 | E3: FY25 | F3: FY26 | G3: Excel formula (latest period) | H3: Interpretation
A4: Current Ratio | B4: Liquidity | C4: =CurrentAssets_FY23/CurrentLiab_FY23 | D4: =CurrentAssets_FY24/CurrentLiab_FY24 | E4: =CurrentAssets_FY25/CurrentLiab_FY25 | F4: =CurrentAssets_FY26/CurrentLiab_FY26 | G4: CurrentAssets_FY26/CurrentLiab_FY26 | H4: Current assets per $1 of current liabilities; >1 covers near-term bills.
A5: Quick (Acid-Test) Ratio | B5: Liquidity | C5: =(CurrentAssets_FY23-Inventory_FY23)/CurrentLiab_FY23 | D5: =(CurrentAssets_FY24-Inventory_FY24)/CurrentLiab_FY24 | E5: =(CurrentAssets_FY25-Inventory_FY25)/CurrentLiab_FY25 | F5: =(CurrentAssets_FY26-Inventory_FY26)/CurrentLiab_FY26 | G5: (CurrentAssets_FY26-Inventory_FY26)/CurrentLiab_FY26 | H5: Liquidity excluding inventory; >1 is conservative coverage.
A6: Net Working Capital | B6: Liquidity | C6: =CurrentAssets_FY23-CurrentLiab_FY23 | D6: =CurrentAssets_FY24-CurrentLiab_FY24 | E6: =CurrentAssets_FY25-CurrentLiab_FY25 | F6: =CurrentAssets_FY26-CurrentLiab_FY26 | G6: CurrentAssets_FY26-CurrentLiab_FY26 | H6: Current assets minus current liabilities; the operating cushion.
A7: NWC-to-Total-Assets | B7: Liquidity | C7: =(CurrentAssets_FY23-CurrentLiab_FY23)/TotalAssets_FY23 | D7: =(CurrentAssets_FY24-CurrentLiab_FY24)/TotalAssets_FY24 | E7: =(CurrentAssets_FY25-CurrentLiab_FY25)/TotalAssets_FY25 | F7: =(CurrentAssets_FY26-CurrentLiab_FY26)/TotalAssets_FY26 | G7: (CurrentAssets_FY26-CurrentLiab_FY26)/TotalAssets_FY26 | H7: Share of assets funded as working-capital cushion.
A8: Inventory Turnover | B8: Activity | C8: =COGS_FY23/Inventory_FY23 | D8: =COGS_FY24/AVERAGE(Inventory_FY24,Inventory_FY23) | E8: =COGS_FY25/AVERAGE(Inventory_FY25,Inventory_FY24) | F8: =COGS_FY26/AVERAGE(Inventory_FY26,Inventory_FY25) | G8: COGS_FY26/AVERAGE(Inventory_FY26,Inventory_FY25) | H8: Times inventory sold per year; higher = leaner stock.
A9: Days Sales in Inventory | B9: Activity | C9: =365/(COGS_FY23/Inventory_FY23) | D9: =365/(COGS_FY24/AVERAGE(Inventory_FY24,Inventory_FY23)) | E9: =365/(COGS_FY25/AVERAGE(Inventory_FY25,Inventory_FY24)) | F9: =365/(COGS_FY26/AVERAGE(Inventory_FY26,Inventory_FY25)) | G9: 365/(COGS_FY26/AVERAGE(Inventory_FY26,Inventory_FY25)) | H9: Days of inventory on hand; lower = faster conversion to cash.
A10: Collection Period (DSO) | B10: Activity | C10: =AR_FY23/(Sales_FY23/365) | D10: =AR_FY24/(Sales_FY24/365) | E10: =AR_FY25/(Sales_FY25/365) | F10: =AR_FY26/(Sales_FY26/365) | G10: AR_FY26/(Sales_FY26/365) | H10: Average days to collect receivables; lower is better.
A11: Fixed Asset Turnover | B11: Activity | C11: =Sales_FY23/NetFixedAssets_FY23 | D11: =Sales_FY24/NetFixedAssets_FY24 | E11: =Sales_FY25/NetFixedAssets_FY25 | F11: =Sales_FY26/NetFixedAssets_FY26 | G11: Sales_FY26/NetFixedAssets_FY26 | H11: Sales generated per $1 of net fixed assets.
A12: Total Asset Turnover | B12: Activity | C12: =Sales_FY23/TotalAssets_FY23 | D12: =Sales_FY24/TotalAssets_FY24 | E12: =Sales_FY25/TotalAssets_FY25 | F12: =Sales_FY26/TotalAssets_FY26 | G12: Sales_FY26/TotalAssets_FY26 | H12: Sales generated per $1 of total assets.
A13: Debt Ratio | B13: Leverage | C13: =TotalLiab_FY23/TotalAssets_FY23 | D13: =TotalLiab_FY24/TotalAssets_FY24 | E13: =TotalLiab_FY25/TotalAssets_FY25 | F13: =TotalLiab_FY26/TotalAssets_FY26 | G13: TotalLiab_FY26/TotalAssets_FY26 | H13: Share of assets financed by liabilities; lower = less risk.
A14: Debt-to-Equity (LT) | B14: Leverage | C14: =LongTermDebt_FY23/TotalEquity_FY23 | D14: =LongTermDebt_FY24/TotalEquity_FY24 | E14: =LongTermDebt_FY25/TotalEquity_FY25 | F14: =LongTermDebt_FY26/TotalEquity_FY26 | G14: LongTermDebt_FY26/TotalEquity_FY26 | H14: Long-term debt per $1 of equity.
A15: Total Debt-to-Equity | B15: Leverage | C15: =TotalLiab_FY23/TotalEquity_FY23 | D15: =TotalLiab_FY24/TotalEquity_FY24 | E15: =TotalLiab_FY25/TotalEquity_FY25 | F15: =TotalLiab_FY26/TotalEquity_FY26 | G15: TotalLiab_FY26/TotalEquity_FY26 | H15: All liabilities per $1 of equity.
A16: Times Interest Earned | B16: Leverage | C16: =EBIT_FY23/Interest_FY23 | D16: =EBIT_FY24/Interest_FY24 | E16: =EBIT_FY25/Interest_FY25 | F16: =EBIT_FY26/Interest_FY26 | G16: EBIT_FY26/Interest_FY26 | H16: EBIT coverage of interest; >3 is comfortable.
A17: Cash Coverage | B17: Leverage | C17: =(EBIT_FY23+Depreciation_FY23)/Interest_FY23 | D17: =(EBIT_FY24+Depreciation_FY24)/Interest_FY24 | E17: =(EBIT_FY25+Depreciation_FY25)/Interest_FY25 | F17: =(EBIT_FY26+Depreciation_FY26)/Interest_FY26 | G17: (EBIT_FY26+Depreciation_FY26)/Interest_FY26 | H17: Interest coverage adding back non-cash depreciation.
A18: Fixed Charge Coverage | B18: Leverage | C18: =(EBIT_FY23+LeasePayments_FY23)/(Interest_FY23+LeasePayments_FY23) | D18: =(EBIT_FY24+LeasePayments_FY24)/(Interest_FY24+LeasePayments_FY24) | E18: =(EBIT_FY25+LeasePayments_FY25)/(Interest_FY25+LeasePayments_FY25) | F18: =(EBIT_FY26+LeasePayments_FY26)/(Interest_FY26+LeasePayments_FY26) | G18: (EBIT_FY26+LeasePayments_FY26)/(Interest_FY26+LeasePayments_FY26) | H18: Coverage of interest + lease obligations.
A19: Equity Multiplier | B19: Leverage | C19: =TotalAssets_FY23/TotalEquity_FY23 | D19: =TotalAssets_FY24/TotalEquity_FY24 | E19: =TotalAssets_FY25/TotalEquity_FY25 | F19: =TotalAssets_FY26/TotalEquity_FY26 | G19: TotalAssets_FY26/TotalEquity_FY26 | H19: Assets per $1 of equity; the leverage factor in DuPont.
A20: Gross Profit Margin | B20: Profitability | C20: =GrossProfit_FY23/Sales_FY23 | D20: =GrossProfit_FY24/Sales_FY24 | E20: =GrossProfit_FY25/Sales_FY25 | F20: =GrossProfit_FY26/Sales_FY26 | G20: GrossProfit_FY26/Sales_FY26 | H20: Gross profit per $1 of sales.
A21: Net Profit Margin | B21: Profitability | C21: =NetIncome_FY23/Sales_FY23 | D21: =NetIncome_FY24/Sales_FY24 | E21: =NetIncome_FY25/Sales_FY25 | F21: =NetIncome_FY26/Sales_FY26 | G21: NetIncome_FY26/Sales_FY26 | H21: Bottom-line profit per $1 of sales.
A22: Return on Assets (ROA) | B22: Profitability | C22: =NetIncome_FY23/TotalAssets_FY23 | D22: =NetIncome_FY24/TotalAssets_FY24 | E22: =NetIncome_FY25/TotalAssets_FY25 | F22: =NetIncome_FY26/TotalAssets_FY26 | G22: NetIncome_FY26/TotalAssets_FY26 | H22: Net income per $1 of assets.
A23: Return on Equity (ROE) | B23: Profitability | C23: =NetIncome_FY23/TotalEquity_FY23 | D23: =NetIncome_FY24/TotalEquity_FY24 | E23: =NetIncome_FY25/TotalEquity_FY25 | F23: =NetIncome_FY26/TotalEquity_FY26 | G23: NetIncome_FY26/TotalEquity_FY26 | H23: Net income per $1 of equity.
A24: Earnings per Share (EPS) | B24: Profitability | C24: =(NetIncome_FY23)/DilutedShares_FY23 | D24: =(NetIncome_FY24)/DilutedShares_FY24 | E24: =(NetIncome_FY25)/DilutedShares_FY25 | F24: =(NetIncome_FY26)/DilutedShares_FY26 | G24: (NetIncome_FY26)/DilutedShares_FY26 | H24: Earnings attributable to each common share.
A25: Price/Earnings (P/E) | B25: Profitability | C25: n/a | D25: n/a | E25: n/a | F25: n/a | G25: Price/EPS_FY26 | H25: Price paid per $1 of annual earnings.
A26: Market-to-Book | B26: Profitability | C26: n/a | D26: n/a | E26: n/a | F26: n/a | G26: Price/BookValuePS | H26: Market price relative to accounting book value per share.
A27: ROE (DuPont 3-step) | B27: DuPont | C27: =(NetIncome_FY23/Sales_FY23)*(Sales_FY23/TotalAssets_FY23)*(TotalAssets_FY23/TotalEquity_FY23) | D27: =(NetIncome_FY24/Sales_FY24)*(Sales_FY24/TotalAssets_FY24)*(TotalAssets_FY24/TotalEquity_FY24) | E27: =(NetIncome_FY25/Sales_FY25)*(Sales_FY25/TotalAssets_FY25)*(TotalAssets_FY25/TotalEquity_FY25) | F27: =(NetIncome_FY26/Sales_FY26)*(Sales_FY26/TotalAssets_FY26)*(TotalAssets_FY26/TotalEquity_FY26) | G27: (NetIncome_FY26/Sales_FY26)*(Sales_FY26/TotalAssets_FY26)*(TotalAssets_FY26/TotalEquity_FY26) | H27: ROE = Net Margin x Asset Turnover x Equity Multiplier.
A28: ROE (ROA x leverage) | B28: DuPont | C28: =(NetIncome_FY23/TotalAssets_FY23)*(1+TotalLiab_FY23/TotalEquity_FY23) | D28: =(NetIncome_FY24/TotalAssets_FY24)*(1+TotalLiab_FY24/TotalEquity_FY24) | E28: =(NetIncome_FY25/TotalAssets_FY25)*(1+TotalLiab_FY25/TotalEquity_FY25) | F28: =(NetIncome_FY26/TotalAssets_FY26)*(1+TotalLiab_FY26/TotalEquity_FY26) | G28: (NetIncome_FY26/TotalAssets_FY26)*(1+TotalLiab_FY26/TotalEquity_FY26) | H28: Cross-check: ROE = ROA x (1 + Total Debt/Equity).
A30: Green = healthy, red = weak (vs. generic thresholds; fills reflect loaded data).
A32: Educational analysis only -- NOT investment, tax, or legal advice. Consult a licensed advisor before acting. Every figure ties to an input cell or cited SEC filing; missing inputs are excluded, never invented.

Sheet Valuation
A1: Valuation -- WACC / DCF / Gordon / Multiples
A3: Cost of Capital
A4: After-tax cost of debt k_d | B4: =(1-'Assumptions'!$B$13)*'Assumptions'!$B$18 | C4: (1 - T) x pre-tax YTM
A5: Cost of equity k_e (CAPM) | B5: ='Assumptions'!$B$9+'Assumptions'!$B$11*('Assumptions'!$B$10-'Assumptions'!$B$9) | C5: Rf + beta x (E(Rm) - Rf)
A6: Cost of preferred k_p | B6: =IF('Assumptions'!$B$4=0,0,'Assumptions'!$B$7/('Assumptions'!$B$4*(1-'Assumptions'!$B$14))) | C6: D_p / (P_p (1 - f)) [proxy]
A7: Weight of debt W_d | B7: =IF(('Inputs'!$E$31+'Inputs'!$E$35)=0,0,'Inputs'!$E$31/('Inputs'!$E$31+'Inputs'!$E$35)) | C7: Market/structure weight
A8: Weight of equity W_e | B8: =IF(('Inputs'!$E$31+'Inputs'!$E$35)=0,0,'Inputs'!$E$35/('Inputs'!$E$31+'Inputs'!$E$35))
A9: WACC | B9: =B7*B4+B8*B5 | C9: W_d k_d + W_e k_e
A11: Discounted Cash Flow (illustrative)
A12: Base free cash flow (CFO - CapEx) | B12: ='Inputs'!$E$38-'Inputs'!$E$43 | C12: From latest cash-flow statement
A13: Projection growth g (Assumptions) | B13: ='Assumptions'!$B$8
A14: Year | B14: 1 | C14: 2 | D14: 3 | E14: 4 | F14: 5 | G14: Terminal
A15: Projected FCF | B15: =B12*(1+B13) | C15: =B15*(1+B13) | D15: =C15*(1+B13) | E15: =D15*(1+B13) | F15: =E15*(1+B13) | G15: =IF((B9-B13)<=0,0,F15*(1+B13)/(B9-B13))
A16: PV of explicit FCF (yrs 1-5) | B16: =NPV(B9,C15:F15)
A17: PV of terminal value | B17: =G15/((1+B9)^5)
A18: Enterprise value (DCF) | B18: =B16+B17
A19: Intrinsic value per share (EV/shares) | B19: =IF('Inputs'!$E$16=0,0,B18/'Inputs'!$E$16)
A20: Market price per share | B20: ='Assumptions'!$B$4
A21: Upside / (downside) vs market | B21: =IF('Assumptions'!$B$4=0,0,B19/'Assumptions'!$B$4-1)
A23: Cross-checks
A24: Gordon-growth value = D0(1+g)/(k_e - g) | B24: =IF((B5-B13)<=0,0,'Assumptions'!$B$7*(1+B13)/(B5-B13))
A25: Multiples value = EPS x assumed P/E (15x) | B25: ='Inputs'!$E$17*15
A27: Educational analysis only -- NOT investment, tax, or legal advice. Consult a licensed advisor before acting. Every figure ties to an input cell or cited SEC filing; missing inputs are excluded, never invented.

Sheet CapBudget
A1: Capital Budgeting -- editable project (sec 4.7)
A2: Edit the cash flows; NPV / IRR / PI / payback recalc live.
A4: Required return k (uses WACC if set) | B4: =IF(Valuation!B9>0,Valuation!B9,Assumptions!$B$12)
A6: Year | B6: 0 | C6: 1 | D6: 2 | E6: 3 | F6: 4 | G6: 5
A7: Net cash flow (NCF) | B7: -100000 | C7: 30000 | D7: 35000 | E7: 40000 | F7: 30000 | G7: 25000
A8: Cumulative cash flow | B8: =B7 | C8: =B8+C7 | D8: =C8+D7 | E8: =D8+E7 | F8: =E8+F7 | G8: =F8+G7
A10: NPV | B10: =B7+NPV(B4,C7:G7) | D10: =-outlay + PV(future NCF)
A11: IRR | B11: =IRR(B7:G7)
A12: Profitability Index (PI) | B12: =IF(B7=0,0,NPV(B4,C7:G7)/-B7) | D12: PV future / initial outlay
A13: Payback (yrs, approx) | B13: =MATCH(TRUE,INDEX(C8:G8>=0,0),0) | D13: First year cumulative >= 0
A14: Accounting Rate of Return (ARR) | B14: =AVERAGE(C7:G7)/(-B7/2) | D14: avg income / avg book value
A16: Decision rules
A17: NPV rule (>0 accept) | B17: =IF(B10>0,"ACCEPT","REJECT")
A18: IRR rule (>k accept) | B18: =IF(B11>B4,"ACCEPT","REJECT")
A19: PI rule (>1 accept) | B19: =IF(B12>1,"ACCEPT","REJECT")
A21: NPV profile (for chart)
A22: Discount rate | B22: NPV
A23: 0 | B23: =B7+NPV(A23,C7:G7)
A24: 0.05 | B24: =B7+NPV(A24,C7:G7)
A25: 0.1 | B25: =B7+NPV(A25,C7:G7)
A26: 0.15 | B26: =B7+NPV(A26,C7:G7)
A27: 0.2 | B27: =B7+NPV(A27,C7:G7)
A28: 0.25 | B28: =B7+NPV(A28,C7:G7)
A29: 0.3 | B29: =B7+NPV(A29,C7:G7)
A31: Educational analysis only -- NOT investment, tax, or legal advice. Consult a licensed advisor before acting. Every figure ties to an input cell or cited SEC filing; missing inputs are excluded, never invented.

Sheet Charts
A1: Charts
A22: Intrinsic vs Market (per share)
A23: Intrinsic | B23: =Valuation!B19
A24: Market | B24: =Assumptions!$B$4
A60: Educational analysis only -- NOT investment, tax, or legal advice. Consult a licensed advisor before acting. Every figure ties to an input cell or cited SEC filing; missing inputs are excluded, never invented.
